Traceback (most recent call last):
  File "<stdin>", line 3, in <module>
  File "/Users/zguo/.pyenv/versions/anaconda3-5.0.1/lib/python3.6/site-packages/matplotlib/pyplot.py", line 34, in <module>
    from matplotlib import rcsetup, style
  File "/Users/zguo/.pyenv/versions/anaconda3-5.0.1/lib/python3.6/site-packages/matplotlib/style/__init__.py", line 1, in <module>
    from .core import use, context, available, library, reload_library
  File "/Users/zguo/.pyenv/versions/anaconda3-5.0.1/lib/python3.6/site-packages/matplotlib/style/core.py", line 222, in <module>
    reload_library()
  File "/Users/zguo/.pyenv/versions/anaconda3-5.0.1/lib/python3.6/site-packages/matplotlib/style/core.py", line 221, in reload_library
    available[:] = library = update_user_library(_base_library)
  File "/Users/zguo/.pyenv/versions/anaconda3-5.0.1/lib/python3.6/site-packages/matplotlib/style/core.py", line 167, in update_user_library
    styles = read_style_directory(stylelib_path)
  File "/Users/zguo/.pyenv/versions/anaconda3-5.0.1/lib/python3.6/site-packages/matplotlib/style/core.py", line 188, in read_style_directory
    use_default_template=False)
  File "/Users/zguo/.pyenv/versions/anaconda3-5.0.1/lib/python3.6/site-packages/matplotlib/__init__.py", line 1062, in rc_params_from_file
    config_from_file = _rc_params_in_file(fname, fail_on_error)
  File "/Users/zguo/.pyenv/versions/anaconda3-5.0.1/lib/python3.6/site-packages/matplotlib/__init__.py", line 980, in _rc_params_in_file
    for line in fd:
  File "/Users/zguo/.pyenv/versions/anaconda3-5.0.1/lib/python3.6/encodings/ascii.py", line 26, in decode
    return codecs.ascii_decode(input, self.errors)[0]
UnicodeDecodeError: 'ascii' codec can't decode byte 0xe6 in position 2: ordinal not in range(128)
